<mujoco model="ur5gripper">
    <compiler angle="radian"
              inertiafromgeom="true"
              texturedir="textures/"
              meshdir="mesh/visual/"/>
    <option timestep="2e-3"
            iterations="100"
            tolerance="1e-10"
            impratio="10"/>
    <default>
        <site rgba="0.8 0.6 0.7 0.3" type="ellipsoid" group="3"/>
        <geom contype='1' conaffinity='1' condim='4'  margin="1e-3" solref=".01 1" solimp=".99 .99 .01" />
        <joint armature="0.01" damping=".1"/>
        <default class="UR5">
            <joint damping='65'/>
        </default>
        <default class="UR5e">
            <joint damping='45'/>
        </default>
        <default class="GRIPPER">
            <joint damping='5'/>
        </default>
    </default>

    <visual>
        <map fogstart="3" fogend="5" znear="0.05"/>
        <quality shadowsize="2048"/>
        <scale framelength="0.1"
               framewidth="0.005"
               contactwidth="0.1"
               contactheight="0.005"
               forcewidth="0.01"
               />
    </visual>

    <!--Assets-->
    <asset>
        <!--Meshes-->
        <mesh name="base"           file="base.stl"     />
        <mesh name="shoulder"       file="shoulder.stl" />
        <mesh name="upperarm"       file="upperarm.stl" />
        <mesh name="forearm"        file="forearm.stl"  />
        <mesh name="wrist1"         file="wrist1.stl"   />
        <mesh name="wrist2"         file="wrist2.stl"   />
        <mesh name="wrist3"         file="wrist3.stl"   />
        <mesh name="gripperpalm"    file="palm.STL"     />
        <mesh name="link_0"         file="link_0.STL"   />
        <mesh name="link_1"         file="link_1.STL"   />
        <mesh name="link_2"         file="link_2.STL"   />
        <mesh name="link_3"         file="link_3.STL"   />

        <mesh name="robotiq_85_base_link_coarse" file="robotiq_85_base_link_coarse.STL" />
        <mesh name="inner_knuckle_coarse" file="inner_knuckle_coarse.STL" />
        <mesh name="inner_finger_coarse" file="inner_finger_coarse.STL" />
        <mesh name="outer_knuckle_coarse" file="outer_knuckle_coarse.STL" />
        <mesh name="outer_finger_coarse" file="outer_finger_coarse.STL" />

        <mesh name="robotiq_85_gripper_adapter_plate" file="robotiq_85_gripper_adapter_plate.stl" />
        <mesh name="robotiq_85_gripper_base" file="robotiq_85_gripper_base.stl" />
        <mesh name="robotiq_85_gripper_joint_0_L" file="robotiq_85_gripper_joint_0_L.stl" />
        <mesh name="robotiq_85_gripper_joint_1_L" file="robotiq_85_gripper_joint_1_L.stl" />
        <mesh name="robotiq_85_gripper_joint_0_R" file="robotiq_85_gripper_joint_0_R.stl" />
        <mesh name="robotiq_85_gripper_joint_1_R" file="robotiq_85_gripper_joint_1_R.stl" />
        <mesh name="robotiq_85_gripper_joint_2_L" file="robotiq_85_gripper_joint_2_L.stl" />
        <mesh name="robotiq_85_gripper_joint_3_L" file="robotiq_85_gripper_joint_3_L.stl" />
        <mesh name="robotiq_85_gripper_joint_2_R" file="robotiq_85_gripper_joint_2_R.stl" />
        <mesh name="robotiq_85_gripper_joint_3_R" file="robotiq_85_gripper_joint_3_R.stl" />

        <!--Textures-->
        <texture name="ur5_tex"     type="2d"       builtin="flat" height="32" width="32" rgb1="0.45 0.45 0.45" />
        <texture name="gripper_tex" type="2d"       builtin="flat" height="32" width="32" rgb1="0.45 0.45 0.45" rgb2="0 0 0"/>
        <texture name="bench_tex"   type="2d"       builtin="flat" height="32" width="32" rgb1="0.7 0.7 0.7" />
        <texture name="sky_tex"     type="skybox"   builtin="gradient" width="100" height="100" rgb1="1 1 1" rgb2="0.3 0.3 0.8" />
        <texture name="texgeom"     type="cube"     builtin="flat" mark="cross" width="127" height="1278" rgb1="0.8 0.6 0.4" rgb2="0.8 0.6 0.4" markrgb="1 1 1" random="0.01" />
        <texture name="floor_tex"   type="2d"        builtin="checker" rgb1=".2 .3 .4" rgb2=".1 .2 .3" width="100" height="100" />
        <texture name="wood"        type="cube"     file="wood2.png"/>
        <texture name="metal"        type="cube"     file="metal2.png"/>
        <!--Materials-->
        <material name="ur5_mat"        texture="ur5_tex"   shininess="0.9" specular="0.75" reflectance="0.3"/>
        <material name="gripper_mat"    texture="gripper_tex"   shininess="0.9" specular="0.75" reflectance="0.4"/>
        <material name='floor_mat'      texture="floor_tex"  shininess="0.8" texrepeat="10 10" specular="0.7"  reflectance="0.5" />
        <material name='geom'           texture="texgeom"   texuniform="true" />
        <material name="bench_mat"      texture="metal"   shininess="0.1" specular="0.5" reflectance="0.2"/>
        <material name="tablecube"      texture="wood" rgba=".8 .8 .8 1"/>
        
        <material name="RobMat" specular="0.9" shininess="0.5" reflectance="0" rgba="0.7 0.7 0.7 1" emission="0.1" />
        <material name="GriMat" specular="0.9" shininess="0.5" reflectance="0" rgba="0.1 0.1 0.1 1" emission="0.1" />
        <material name="BasketMat" specular="0" shininess="0" reflectance="0" rgba="0.26 0.16 0.16796875 1" emission="0" />
    </asset>

    <!--Contacts-->
    <contact>
        <exclude body1="box_link" body2="base_link"/>
        <exclude body1="base_link" body2="shoulder_link"/>
        <exclude body1="shoulder_link" body2="upper_arm_link"/>
        <exclude body1="upper_arm_link" body2="forearm_link"/>
        <exclude body1="forearm_link" body2="wrist_1_link"/>
        <exclude body1="wrist_1_link" body2="wrist_2_link"/>
        <exclude body1="wrist_2_link" body2="wrist_3_link"/>
        <exclude body1="ee_link" body2="wrist_3_link"/>
    </contact>


    <!--MODEL DESCRIPTION-->
    <worldbody>
        <!--Lighting parameters-->
        <light name="light3" mode="targetbody" target="box_link" directional="true" pos="1 -1 3" />
        <!-- <light name="light3" mode="targetbody" target="box_link" directional="true" pos="1 1 3" /> -->
        <!--Camera parameters-->
        <camera name="main1" mode="fixed" target="ee_link" pos="2 2 2.7" axisangle="2 2 -2 1"/>
        <camera name="top_down" mode="fixed" target="ee_link" pos="0 -0.6 2.0" axisangle="2 2 2 0"/>
        <camera name="side" mode="fixed" target="ee_link" pos="0.8 -0.6 1.0" quat="0.5 0.5 0.5 0.5"/>
        <!--Floor Property-->
        <geom name='floor' material="floor_mat" pos='0 0 0' size='2.5 2.5 0.1'  type='plane' />


        <body name="pick_box" pos="0 -0.6 0.0" euler="0 0 1.57">
            <geom size=".2608 .3302 .03" pos ="0 0 0.855" type="box" material="tablecube"/>
            <!-- <geom size=".2 .28 .03" pos ="0 0 0.86" type="box" material="bench_mat" friction="2 0.005 0.0001"/> -->
            <geom size=".03 .27 .44" pos ="0.23 0.0 0.44" type="box" material="tablecube"/>
            <geom size=".03 .27 .44" pos ="-0.23 0.0 0.44" type="box" material="tablecube"/>
            <geom size=".26 .03 .44" pos ="0.0 0.3 0.44" type="box" material="bench_mat"/>
            <geom size=".26 .03 .44" pos ="0.0 -0.3 0.44" type="box" material="bench_mat"/>
            <inertial pos="0 0 0" mass="1000" diaginertia="0 0 0" />
        </body>


        <!--Robot UR5-->
        <body name="box_link" pos="0 0 0.435">
            <!--<geom size=".3 .2 .435" type="box" material="bench_mat"/>-->
            <geom size=".29 .19 .03" pos ="0 0 0.4" type="box" material="bench_mat"/>
            <geom size=".29 .19 .03" pos ="0 0 -0.2" type="box" material="bench_mat"/>
            <geom size=".04 .04 .435" pos =".26 .16 0" type="box" material="bench_mat"/>
            <geom size=".04 .04 .435" pos ="-.26 .16 0" type="box" material="bench_mat"/>
            <geom size=".04 .04 .435" pos =".26 -.16 0" type="box" material="bench_mat"/>
            <geom size=".04 .04 .435" pos ="-.26 -.16 0" type="box" material="bench_mat"/>
            <inertial pos="0 0 0" mass="1000" diaginertia="0 0 0" />
            <body name="base_link" pos="0 0 0.435">
                <inertial pos="0 0 0" quat="0.5 0.5 -0.5 0.5" mass="4" diaginertia="0.0072 0.00443333 0.00443333" />
                <geom type="mesh"  mesh="base" material="RobMat"/>
                <geom name="base_cap" type="cylinder" pos="0 0 0.14" size="0.06 0.02" rgba="0.596 0.96 1 1" material="RobMat" contype="0" conaffinity="0" />

                <body name="shoulder_link" pos="0 0 0.089159">
                    <inertial pos="0 0 0" mass="3.7" diaginertia="0.0102675 0.0102675 0.00666" />
                    <joint name="shoulder_pan_joint" class="UR5" pos="0 0 0" axis="0 0 1" limited="true" range="-3.14159 3.14159" />
                    <geom type="mesh"  mesh="shoulder" material="RobMat"/>
                    <geom name="shoulder_cap" type="cylinder" pos="0 0.185 0" quat="0.707107 0.707107 0 0" size="0.06 0.02" rgba="0.596 0.96 1 1" material="RobMat" contype="0" conaffinity="0" />

                    <body name="upper_arm_link" pos="0 0.13585 0" quat="0.707107 0 0.707107 0">
                        <inertial pos="0 0 0.28" mass="8.393" diaginertia="0.226891 0.226891 0.0151074" />
                        <joint name="shoulder_lift_joint" class="UR5" pos="0 0 0" axis="0 1 0" limited="true" range="-3.14159 0" /> <!--Range= -3.14159 3.14159-->
                        <geom type="mesh"  mesh="upperarm" material="RobMat"/>
                        <body name="forearm_link" pos="0 -0.1197 0.425">
                            <inertial pos="0 0 0.25" mass="2.275" diaginertia="0.0494433 0.0494433 0.004095" />
                            <joint name="elbow_joint" class="UR5" pos="0 0 0" axis="0 1 0" limited="true" range="-3.14159 3.14159" />
                            <geom type="mesh"  mesh="forearm" material="RobMat"/>
                            <geom name="forearm_cap" type="cylinder" pos="0 0.17 0" quat="0.707107 0.707107 0 0" size="0.06 0.02" rgba="0.596 0.96 1 1" material="RobMat" contype="0" conaffinity="0" />#

                            <body name="wrist_1_link" pos="0 0 0.39225" quat="0.707107 0 0.707107 0">
                                <inertial pos="0 0 0" quat="0.5 0.5 -0.5 0.5" mass="1.219" diaginertia="0.21942 0.111173 0.111173" />
                                <joint name="wrist_1_joint" class="UR5e" pos="0 0 0" axis="0 1 0" limited="true" range="-3.14159 3.14159" />
                                <geom type="mesh"  mesh="wrist1" material="RobMat"/>
                                <geom name="wrist1_cap" type="cylinder" pos="0 -0.045 0" quat="0.707107 0.707107 0 0" size="0.04 0.015" rgba="0.596 0.96 1 1" material="RobMat" contype="0" conaffinity="0" />
                                
                                <body name="wrist_2_link" pos="0 0.093 0">
                                    <inertial pos="0 0 0" quat="0.5 0.5 -0.5 0.5" mass="1.219" diaginertia="0.21942 0.111173 0.111173" />
                                    <joint name="wrist_2_joint" class="UR5e" pos="0 0 0" axis="0 0 1" limited="true" range="-3.14159 3.14159" />
                                    <geom type="mesh"  mesh="wrist2" material="RobMat"/>
                                    <geom name="wrist2_cap" type="cylinder" pos="0 0 -0.045" quat="0.707107 0 0 0.707107" size="0.04 0.015" rgba="0.596 0.96 1 1" material="RobMat" contype="0" conaffinity="0" />

                                    <body name="wrist_3_link" pos="0 0 0.09465">
                                        <inertial pos="0 0 0" quat="0.5 0.5 -0.5 0.5" mass="0.1879" diaginertia="0.033822 0.0171365 0.0171365" />
                                        <joint name="wrist_3_joint" class="UR5e" pos="0 0 0" axis="0 1 0" limited="true" range="-3.14159 3.14159" />
                                        <geom type="mesh"  mesh="wrist3" material="RobMat"/>
                                         <geom name="wrist3_cap" type="cylinder" pos="0 -0.045 0" quat="0.707107 0.707107 0 0" size="0.04 0.015" rgba="0.596 0.96 1 1" material="RobMat" contype="0" conaffinity="0" />
                                        <body name="ee_link" pos="0 0.0823 0" quat="0.707107 -0.707107 0 0">
                                            <inertial pos="-0.01 0 0" mass="0.001" diaginertia="1.66667e-08 1.66667e-08 1.66667e-08" />
                                            <geom size="0.005 0.005 0.005" pos="-0.01 0 0" type="box" />

                                        <body name="robotiq_85_adapter_link" pos="0 0 0" quat="0 0.709 0 0.706">
            <inertial pos="0 0 0" mass="0.01" diaginertia="0.001 0.001 0.001" />
            <geom quat="0.500048 0.5 0.499952 0.5" type="mesh" group="0" mesh="robotiq_85_gripper_adapter_plate" />
            <geom quat="0.500048 0.5 0.499952 0.5" type="mesh" contype="0" conaffinity="0" group="1" mesh="robotiq_85_gripper_adapter_plate" />
            <body name="robotiq_85_base_link" pos="0.0085 0 -0.0041">
                <site name="grip_site" pos="0.1 0 0" size="0.01" rgba="1 0 0 1" type="sphere" group="1"/>
                <site name="grip_site_cylinder" pos="-0.02 0 0" quat="0.707 0 0.707 0" size="0.005 10" rgba="0 1 0 0.3" type="cylinder" group="1"></site>
                <inertial pos="0 0 0" mass="0.01" diaginertia="0.001 0.001 0.001" />
                <geom quat="3.27596e-05 0.707141 0.707073 3.27564e-05" type="mesh" group="0" mesh="robotiq_85_gripper_base" />
                <geom quat="3.27596e-05 0.707141 0.707073 3.27564e-05" type="mesh" contype="0" conaffinity="0" group="1" mesh="robotiq_85_gripper_base" />
                <body name="robotiq_85_left_knuckle_link" pos="0.04191 0.0306 0" quat="0.500048 -0.5 0.5 0.499952">
                    <inertial pos="0 0 0" mass="0.01" diaginertia="0.001 0.001 0.001" />
                    <joint name="robotiq_85_left_knuckle_joint" class="GRIPPER" pos="0 0 0" axis="1 0 0" limited="true" range="0 0.8575" />
                    <geom pos="0 0.04191 -0.0306" quat="9.38231e-07 0.707141 -9.3814e-07 0.707073" type="mesh" group="0" mesh="robotiq_85_gripper_joint_0_L" name="robotiq_85_gripper_joint_0_L"/>
                    <geom pos="0 0.04191 -0.0306" quat="9.38231e-07 0.707141 -9.3814e-07 0.707073" type="mesh" contype="0" conaffinity="0" group="1" mesh="robotiq_85_gripper_joint_0_L" />
                    <body name="robotiq_85_left_finger_link" pos="0 0.00508 0.03134" quat="4.63268e-05 1 0 0">
                       <!--  <geom pos="0 0.047 -0.008" size="0.005" type="sphere" rgba="1 0 0 1"/> -->
                        <inertial pos="0 0 0" mass="0.01" diaginertia="0.001 0.001 0.001" />
                        <geom pos="0 -0.03683 0.06194" quat="0.707141 0 0.707073 0" type="mesh" group="0" mesh="robotiq_85_gripper_joint_1_L" name="robotiq_85_gripper_joint_1_L"/>
                        <geom pos="0 -0.03683 0.06194" quat="0.707141 0 0.707073 0" type="mesh" group="1" contype="0" conaffinity="0" mesh="robotiq_85_gripper_joint_1_L" />
                    </body>
                </body>
                <body name="robotiq_85_right_knuckle_link" pos="0.04191 -0.0306 0" quat="0.500048 0.5 -0.5 0.499952">
                    <inertial pos="0 0 0" mass="0.01" diaginertia="0.001 0.001 0.001" />
                    <joint name="robotiq_85_right_knuckle_joint" class="GRIPPER" pos="0 0 0" axis="1 0 0" limited="true" range="0 1.5707" />
                    <geom pos="0 0.04191 -0.0306" quat="9.38231e-07 0.707141 9.3814e-07 -0.707073" type="mesh" group="0" mesh="robotiq_85_gripper_joint_0_R" name="robotiq_85_gripper_joint_0_R"/>
                    <geom pos="0 0.04191 -0.0306" quat="9.38231e-07 0.707141 9.3814e-07 -0.707073" type="mesh" contype="0" conaffinity="0" group="1" mesh="robotiq_85_gripper_joint_0_R" />
                    <body name="robotiq_85_right_finger_link" pos="0 0.00508 0.03134" quat="4.63268e-05 1 0 0">
                        <!-- <geom pos="0 0.047 -0.008" size="0.005" type="sphere" rgba="1 0 0 1"/> -->
                        <inertial pos="0 0 0" mass="0.01" diaginertia="0.001 0.001 0.001" />
                        <geom pos="0 -0.03683 0.06194" quat="0.707141 0 -0.707073 0" type="mesh" group="0" mesh="robotiq_85_gripper_joint_1_R" name="robotiq_85_gripper_joint_1_R"/>
                        <geom pos="0 -0.03683 0.06194" quat="0.707141 0 -0.707073 0" type="mesh" contype="0" conaffinity="0" group="1" mesh="robotiq_85_gripper_joint_1_R" />
                    </body>
                </body>
                <body name="robotiq_85_left_inner_knuckle_link" pos="0.04843 0.0127 0" quat="0.500048 0.5 0.5 -0.499952">
                    <inertial pos="0 0 0" mass="0.01" diaginertia="0.001 0.001 0.001" />
                    <joint name="robotiq_85_left_inner_knuckle_joint" pos="0 0 0" axis="1 0 0" limited="true" range="0 1.5707" />
                    <geom pos="0 -0.04843 0.0127" quat="0.707141 0 0.707073 0" type="mesh" mesh="robotiq_85_gripper_joint_2_L" name="robotiq_85_gripper_joint_2_L"/>
                    <geom pos="0 -0.04843 0.0127" quat="0.707141 0 0.707073 0" type="mesh" contype="0" conaffinity="0" group="1" mesh="robotiq_85_gripper_joint_2_L" />
                    <body name="robotiq_85_left_finger_tip_link" pos="0 0.04196 -0.0388">
                        <!-- <geom pos="0 -0.0065 -0.0185" size="0.005" type="sphere" rgba="0 1 0 1"/> -->
                        <inertial pos="0 0 0" mass="0.01" diaginertia="0.001 0.001 0.001" />
                        <joint name="robotiq_85_left_finger_tip_joint" class="GRIPPER" pos="0 0 0" axis="1 0 0" limited="true" range="0 1.5707" />
                        <geom pos="0 -0.090381 0.051505" quat="0.707141 0 0.707073 0" type="mesh" group="0" mesh="robotiq_85_gripper_joint_3_L" name="robotiq_85_gripper_joint_3_L"/>
                        <geom pos="0 -0.090381 0.051505" quat="0.707141 0 0.707073 0" type="mesh" contype="0" conaffinity="0" group="1" mesh="robotiq_85_gripper_joint_3_L" />
                    </body>
                </body>
                <body name="robotiq_85_right_inner_knuckle_link" pos="0.04843 -0.0127 0" quat="0.500048 -0.5 -0.5 -0.499952">
                    <inertial pos="0 0 0" mass="0.01" diaginertia="0.001 0.001 0.001" />
                    <joint name="robotiq_85_right_inner_knuckle_joint" class="GRIPPER" pos="0 0 0" axis="1 0 0" limited="true" range="0 1.5707" />
                    <geom pos="0 -0.04843 0.0127" quat="0.707141 0 -0.707073 0" type="mesh" contype="4" conaffinity="3" group="0" mesh="robotiq_85_gripper_joint_2_R" name="robotiq_85_gripper_joint_2_R"/>
                    <geom pos="0 -0.04843 0.0127" quat="0.707141 0 -0.707073 0" type="mesh" contype="0" conaffinity="0" group="1" mesh="robotiq_85_gripper_joint_2_R" />
                    <body name="robotiq_85_right_finger_tip_link" pos="0 0.04196 -0.0388">
                        <inertial pos="0 0 0" mass="0.01" diaginertia="0.001 0.001 0.001" />
                        <!-- <geom pos="0 -0.0065 -0.0185" size="0.005" type="sphere" rgba="0 1 0 1"/> -->
                        <joint name="robotiq_85_right_finger_tip_joint" class="GRIPPER" pos="0 0 0" axis="1 0 0" limited="true" range="0 1.5707" />
                        <geom pos="0 -0.090381 0.051505" quat="0.707141 0 -0.707073 0" type="mesh" group="0"  mesh="robotiq_85_gripper_joint_3_R" name="robotiq_85_gripper_joint_3_R"/>
                        <geom pos="0 -0.090381 0.051505" quat="0.707141 0 -0.707073 0" type="mesh" contype="0" conaffinity="0" group="1" mesh="robotiq_85_gripper_joint_3_R" />
                    </body>
                </body>
            </body>
        </body>
                                            </body>
                            </body>
                        </body>
                    </body>
                </body>
            </body>
        </body>
    </body>
                <body name="base" pos="0 0 0" quat="1.7949e-09 0 0 -1">
                    <inertial pos="0 0 0" quat="1.7949e-09 0 0 -1" mass="0" diaginertia="0 0 0" />
                </body>
        </body>


        <body name="target_body" pos=".2 -.55 0.95">
            <geom name="target" pos="0 0 0" size="0.0113 0.06 0.01" type="box" material="bench_mat"  />
            <!--site name="target_site_1" pos="0 0 0" size="0.025 0.025 0.025" type="box" rgba="0.9529411765 0.8 0.03529411765 1" /-->
            <joint name="free_x_1" pos="0 0 0" type="slide" axis="1 0 0" frictionloss="0" damping="0" />
            <joint name="free_y_1" pos="0 0 0" type="slide" axis="0 1 0" frictionloss="0" damping="0" />
            <joint name="free_z_1" pos="0 0 0" type="slide" axis="0 0 1" frictionloss="0" damping="0" />
            <joint name="free_ball_1" pos="0 0 0" type="ball" frictionloss="0" damping="0" />
        </body>



        <body name="platt" pos=".0 -.75 0.95">
            <geom name="target_2" pos="0 0 0" size="0.1 0.01  0.28"  material="tablecube"  type="ellipsoid"  />
            <geom name="target_r" pos=".01 0.1 0.1" size="0.0016 0.1  0.01" material="RobMat" type="box"  />
             <geom name="target_l" pos="-.01 0.1 0.1" size=" 0.0016 0.1 0.01" material="RobMat" type="box" />
             <geom name="target_d" pos="0 0.1 0.11" size="0.0116 0.1 0.001" type="box" material="RobMat"  />
             <geom name="target_a" pos="0 0.1 0.09" size="0.0116 0.1 0.001" type="box" material="RobMat" />
           
            
        </body>



    </worldbody>

<equality>
        <connect body1="robotiq_85_right_finger_link" body2="robotiq_85_right_finger_tip_link" anchor="0 0.047 -0.008"/>
        <connect body1="robotiq_85_left_finger_link" body2="robotiq_85_left_finger_tip_link" anchor="0 0.047 -0.008"/>
    </equality>

 

    <equality>


        <joint name="fingers" joint1="robotiq_85_left_finger_tip_joint" joint2="robotiq_85_right_finger_tip_joint"   polycoef="0 1 0 0 0"/>
    </equality>


    <!--ACTUATORS-->
    <actuator>
        <!--UR5-->

        <motor name='shoulder_pan_T' ctrllimited="true" ctrlrange="-2 2" joint='shoulder_pan_joint' gear="101"/> <!--range -150 150-->
        <motor name='shoulder_lift_T' ctrllimited="true" ctrlrange="-2 2" joint='shoulder_lift_joint' gear="101"/>
        <motor name='forearm_T' ctrllimited="true" ctrlrange="-2 2" joint='elbow_joint' gear="101" />
        <motor name='wrist_1_T' ctrllimited="true" ctrlrange="-1 1" joint='wrist_1_joint' gear="101"/>  <!--range -28 28-->
        <motor name='wrist_2_T' ctrllimited="true" ctrlrange="-1 1" joint='wrist_2_joint' gear="101"/>
        <motor name='wrist_3_T' ctrllimited="true" ctrlrange="-1 1" joint='wrist_3_joint' gear="101"/>



        
        <motor name='gripper_motor' ctrllimited="true" ctrlrange="-1 1" joint='robotiq_85_left_finger_tip_joint' gear="101"/>

    </actuator>


</mujoco>
